Workbook

Sheet ASUS ROG Flow Z13 (2025) GZ302E
F1: § | G1: Input | H1: Description | L1: Note
F2: Identification
C3: Sections below are for calculation only—no data entry. DO NOT ALTER. | F3: 1.1 | G3: ASUS ROG Flow Z13 (2025) GZ302EA-XS96 | H3: Make/Model | L3: A.K.A. GZ302E - midrange model
F4: 1.2 | G4: Tablet | H4: Product Group | L4: * This may be marketed more as a gaming laptop, but it's the usual detachable keyboard / 2-in-1 design that we'd score as a tablet
C5: \/ \/ \/ \/ \/ | F5: 1.3 | G5: Yes | H5: Unique product identifier present on product exterior * | L5: "Model: GZ302E" and "GZ302EA-XS96" printed inside kickstand
F6: 1.4 | H6: * Partial credit: identifier present after minor disassembly | L6: e.g. On SIM tray or underneath pop-off back cover. No tools or the most basic tools only. IMEI numbers still don't count.
A8: Data | B8: Weight | C8: Calc | F8: Documentation (Service Manual)
A9: =if(G9="Yes",1,0) -> 1 | B9: Pass/Fail | F9: 2.1 | G9: Yes | H9: On OEM website / support site, or readily linked therefrom | L9: https://rog.asus.com/us/laptops/rog-flow/rog-flow-z13-2025/helpdesk_service_guide/
A10: =if(G10="Yes",1,0) -> 1 | B10: Pass/Fail | F10: 2.2 | G10: Yes | H10: Free, public | L10: Must not require registration for access—If registration/signup is required, mark this field "No."
A11: =if(G11="Yes",1,0) -> 1 | B11: 0.05 | C11: =A11*B11 -> 0.05 | F11: 2.3 | G11: Yes | H11: Includes tools list(s) | L11: "Screwdriver" is listed, but doesn't say what kind.
A12: =if(G12="Yes",1,0) -> 0 | B12: 0.05 | C12: =A12*B12 -> 0 | F12: 2.4 | G12: No | H12: Includes parts list w/part numbers (or clear compatibility) | L12: If no part numbers, compatibility must be obvious—e.g. if there’s only one Fairphone 4 and only one part named “Fairphone 4 display,” good enough. A direct link in the manual to the correct part's product page is also okay.
A13: =if(G13="Yes",1,0) -> 1 | B13: 0.05 | C13: =A13*B13 -> 0.05 | F13: 2.5 | G13: Yes | H13: Includes exploded diagram
A14: =if(G14="Yes",1,0) -> 0 | B14: 0.05 | C14: =A14*B14 -> 0 | F14: 2.6 | G14: No | H14: Includes schematics (board diagrams) | L14: There's a single connection diagram on p. 96—nothing helpful for board-level repair.
A15: =if(G15="Yes",1,0) -> 0 | B15: 0.05 | C15: =A15*B15 -> 0 | F15: 2.7 | G15: No | H15: Includes troubleshooting | L15: Refers reader to diagnostic tools on the Asus support site.
A16: =if(G16="Yes",if(hlookup($G$4,'Scored Components + Weights'!$1:$17,5,FALSE)>0,1,0),0) -> #REF! | B16: =IF(ISNUMBER(SEARCH("N/A",H16)),0,if(G16="N/A",0,(1-SUM($B$11:$B$15))/(((7-countif($G$16:$G$22,"N/A")))))) -> 0.125 | C16: =A16*B16 -> #REF! | F16: 2.8 | G16: Yes | H16: =concat("Includes repair guide for Scored Component 1 — ",$G$94) -> #REF! | L16: Videos okay. If missing, check in owner's manual before marking incomplete.
A17: =if(G17="Yes",if(hlookup($G$4,'Scored Components + Weights'!$1:$17,7,FALSE)>0,1,0),0) -> #REF! | B17: =IF(ISNUMBER(SEARCH("N/A",H17)),0,if(G17="N/A",0,(1-SUM($B$11:$B$15))/(((7-countif($G$16:$G$22,"N/A")))))) -> 0.125 | C17: =A17*B17 -> #REF! | F17: 2.8a | G17: Yes | H17: =concat(" ... for Scored Component 2 — ",$G$150) -> #REF! | L17: Be sure to enter "N/A" for any components that could not reasonably have a repair procedure, e.g. soldered RAM. Design choices are penalized elsewhere in the scorecard, not here.
A18: =if(G18="Yes",if(hlookup($G$4,'Scored Components + Weights'!$1:$17,9,FALSE)>0,1,0),0) -> 0 | B18: =IF(ISNUMBER(SEARCH("N/A",H18)),0,if(G18="N/A",0,(1-SUM($B$11:$B$15))/(((7-countif($G$16:$G$22,"N/A")))))) -> 0 | C18: =A18*B18 -> 0 | F18: 2.8b | G18: N/A | H18: =concat(" ... for Scored Component 3 — ",$G$206) -> #REF! | L18: In other words, we want to see the completest service manual that could reasonably exist for this device—not for an imaginary device. If the OEM makes a product that's not well designed for repair with an A+ repair manual, they get 100% credit here.
A19: =if(G19="Yes",if(hlookup($G$4,'Scored Components + Weights'!$1:$17,11,FALSE)>0,1,0),0) -> #REF! | B19: =IF(ISNUMBER(SEARCH("N/A",H19)),0,if(G19="N/A",0,(1-SUM($B$11:$B$15))/(((7-countif($G$16:$G$22,"N/A")))))) -> 0.125 | C19: =A19*B19 -> #REF! | F19: 2.8c | G19: Yes | H19: =concat(" ... for Scored Component 4 — ",$G$262) -> #REF!
A20: =if(G20="Yes",if(hlookup($G$4,'Scored Components + Weights'!$1:$17,13,FALSE)>0,1,0),0) -> #REF! | B20: =IF(ISNUMBER(SEARCH("N/A",H20)),0,if(G20="N/A",0,(1-SUM($B$11:$B$15))/(((7-countif($G$16:$G$22,"N/A")))))) -> 0.125 | C20: =A20*B20 -> #REF! | F20: 2.8d | G20: Yes | H20: =concat(" ... for Scored Component 5 — ",$G$318) -> #REF!
A21: =if(G21="Yes",if(hlookup($G$4,'Scored Components + Weights'!$1:$17,15,FALSE)>0,1,0),0) -> #REF! | B21: =IF(ISNUMBER(SEARCH("N/A",H21)),0,if(G21="N/A",0,(1-SUM($B$11:$B$15))/(((7-countif($G$16:$G$22,"N/A")))))) -> 0.125 | C21: =A21*B21 -> #REF! | F21: 2.8e | G21: Yes | H21: =concat(" ... for Scored Component 6 — ",$G$374) -> #REF!
A22: =if(G22="Yes",if(hlookup($G$4,'Scored Components + Weights'!$1:$17,17,FALSE)>0,1,0),0) -> 0 | B22: =IF(ISNUMBER(SEARCH("N/A",H22)),0,if(G22="N/A",0,(1-SUM($B$11:$B$15))/(((7-countif($G$16:$G$22,"N/A")))))) -> 0.125 | C22: =A22*B22 -> 0 | F22: 2.8f | G22: =IF(ISNUMBER(SEARCH("N/A",H22)), "N/A","") | H22: =concat(" ... for Scored Component 7 — ",$G$430) -> #REF!
A24: Subtotal | B24: =sum(B11:B22) -> 1 | C24: =sum(C11:C22) -> #REF! | F24: 2.11 | G24: =ifs(G5="","",G5="YES",if(A9+A10=2,C24,0),G6="YES",if(if(A9+A10=2,C24,0)>0.9,0.9,if(A9+A10=2,C24,0)),G5="NO",if(if(A9+A10=2,C24,0)>0.85,0.85,if(A9+A10=2,C24,0))) -> #REF! | H24: Documentation Subtotal | L24: Capped at 85% if unique product identifier is not present (§1.3), or 90% if only present after minor disassembly (§1.4).
F25: Replacement Parts
F26: 3.1 | G26: 2399.99 | H26: Retail price of this device (excluding tax/shipping) | L26: Seemingly no parts available unless you confirm a hardware problem using Asus' diagnostic tool and successfully APPLY for the right to purchase the specified component. https://www.asus.com/us/support/customer-self-repair/
F27: 3.2 | G27: Replacement part pricing / availability | L27: Googling turns up a whole separate site for spare parts, most of which are out of stock, but it appears this may be a legitimate authorized parts source. Unfortunately I can find no reference to it on the official support site, so as of now this does not qualify for scoring: https://partshop.asus.com/us/
A28: Ratio of Part Price / MSRP | B28: Weight | C28: Credit Awarded | D28: Weighted Total | G28: Price | H28: Part | J28: Standard Part (or N/A) | K28: Not For Sale | L28: Checking "Standard Part (or N/A)" indicates the device either uses a widely available off-the-shelf or commodity part like a AA battery, m.2 SSD, etc., or else has eliminated the scored component from the design (e.g. a fanless laptop). This awards full credit automagically and "Price" is not required (and will be ignored). Checking "Not For Sale" indicates a custom or proprietary part that is not readily available for sale from the OEM or authorized 3rd party at the time of the assessment. This incurs a penalty. Note: If a component is only available as part of a larger assembly, enter the price of the assembly rather than marking the part "not for sale." (e.g. if RAM or storage is soldered to the motherboard, enter the price of the entire motherboard.) This includes soldered LPDDR. If a component is truly not applicable—for example, a fanless laptop design where there is no fan to ever fail or need replacing—check "Standard Part" for automatic full credit.
A29: =G29/G$26 -> 0.26951362 | B29: =HLOOKUP(G4,'Scored Components + Weights'!C1:V17,5,FALSE) -> #REF! | C29: =if(J29=TRUE,1,if(K29=TRUE,0,if(G29="",0,if(A29<0.2501,1,if(A29>1,0,0.2))))) -> 0 | D29: =B29*C29 -> #REF! | F29: 3.2a | G29: 646.83 | H29: =concat(" Scored Component 1 — ",$G$94) -> #REF! | J29: FALSE | K29: TRUE | L29: =if(J29=TRUE,if(K29=TRUE,"ERROR! You can't check both boxes. A standard part by definition is always for sale. Note, it does NOT need to be for sale from the OEM—standard parts like RAM sticks or M.2 SSDs are already available at many retailers.",""),"")
A30: =G30/G$26 -> 0.058421077 | B30: =HLOOKUP(G4,'Scored Components + Weights'!C1:V17,7,FALSE) -> #REF! | C30: =if(J30=TRUE,1,if(K30=TRUE,0,if(G30="",0,if(A30<0.2501,1,if(A30>1,0,0.2))))) -> 0 | D30: =B30*C30 -> #REF! | F30: 3.2b | G30: 140.21 | H30: =concat(" Scored Component 2 — ",$G$150) -> #REF! | J30: FALSE | K30: TRUE | L30: =if(J30=TRUE,if(K30=TRUE,"ERROR! You can't check both boxes. A standard part by definition is always for sale. Note, it does NOT need to be for sale from the OEM—standard parts like RAM sticks or M.2 SSDs are already available at many retailers.",""),"")
A31: =G31/G$26 -> 1.0009875 | B31: =HLOOKUP(G4,'Scored Components + Weights'!C1:V17,9,FALSE) -> #REF! | C31: =if(J31=TRUE,1,if(K31=TRUE,0,if(G31="",0,if(A31<0.2501,1,if(A31>1,0,0.2))))) -> 0 | D31: =B31*C31 -> #REF! | F31: 3.2c | G31: 2402.36 | H31: =concat(" Scored Component 3 — ",$G$206) -> #REF! | J31: FALSE | K31: TRUE | L31: =if(J31=TRUE,if(K31=TRUE,"ERROR! You can't check both boxes. A standard part by definition is always for sale. Note, it does NOT need to be for sale from the OEM—standard parts like RAM sticks or M.2 SSDs are already available at many retailers.",""),"")
A32: =G32/G$26 -> 0.014237559 | B32: =HLOOKUP(G4,'Scored Components + Weights'!C1:V17,11,FALSE) -> #REF! | C32: =if(J32=TRUE,1,if(K32=TRUE,0,if(G32="",0,if(A32<0.2501,1,if(A32>1,0,0.2))))) -> 0 | D32: =B32*C32 -> #REF! | F32: 3.2d | G32: 34.17 | H32: =concat(" Scored Component 4 — ",$G$262) -> #REF! | J32: FALSE | K32: TRUE | L32: =if(J32=TRUE,if(K32=TRUE,"ERROR! You can't check both boxes. A standard part by definition is always for sale. Note, it does NOT need to be for sale from the OEM—standard parts like RAM sticks or M.2 SSDs are already available at many retailers.",""),"")
A33: =G33/G$26 -> 0.014237559 | B33: =HLOOKUP(G4,'Scored Components + Weights'!C1:V17,13,FALSE) -> #REF! | C33: =if(J33=TRUE,1,if(K33=TRUE,0,if(G33="",0,if(A33<0.2501,1,if(A33>1,0,0.2))))) -> 0 | D33: =B33*C33 -> #REF! | F33: 3.2e | G33: 34.17 | H33: =concat(" Scored Component 5 — ",$G$318) -> #REF! | J33: FALSE | K33: TRUE | L33: =if(J33=TRUE,if(K33=TRUE,"ERROR! You can't check both boxes. A standard part by definition is always for sale. Note, it does NOT need to be for sale from the OEM—standard parts like RAM sticks or M.2 SSDs are already available at many retailers.",""),"")
A34: =G34/G$26 -> 0 | B34: =HLOOKUP(G4,'Scored Components + Weights'!C1:V17,15,FALSE) -> #REF! | C34: =if(J34=TRUE,1,if(K34=TRUE,0,if(G34="",0,if(A34<0.2501,1,if(A34>1,0,0.2))))) -> 1 | D34: =B34*C34 -> #REF! | F34: 3.2f | H34: =concat(" Scored Component 6 — ",$G$374) -> #REF! | J34: TRUE | K34: FALSE | L34: M.2 SSD
A35: =G35/G$26 -> 0 | B35: =HLOOKUP(G4,'Scored Components + Weights'!C1:V17,17,FALSE) -> #REF! | C35: =if(J35=TRUE,1,if(K35=TRUE,0,if(G35="",0,if(A35<0.2501,1,if(A35>1,0,0.2))))) -> 0 | D35: =B35*C35 -> #REF! | F35: 3.2g | H35: =concat(" Scored Component 7 — ",$G$430) -> #REF! | J35: FALSE | K35: TRUE | L35: =if(J35=TRUE,if(K35=TRUE,"ERROR! You can't check both boxes. A standard part by definition is always for sale. Note, it does NOT need to be for sale from the OEM—standard parts like RAM sticks or M.2 SSDs are already available at many retailers.",""),"")
F37: 3.5 | G37: =ifs(G5="","",G5="YES",SUM(D29:D35),G6="YES",if(sum(D29:D35)>0.9,0.9,sum(D29:D35)),G5="NO",if(sum(D29:D35)>0.85,0.85,SUM(D29:D35))) -> #REF! | H37: Parts Subtotal | L37: Capped at 85% if unique product identifier is not present (§1.3), or 90% if only present after minor disassembly (§1.4).
F38: Tools
G39: Tool Utilized | I39: Tool Score | J39: Used in [X] Procedures | K39: Total Number of Uses | L39: Tools criterion is primarily about availability, including cost and convenience of access. In all cases the technician should default to basic (Class A) tools, using more expensive/specialized tools only when necessary.
F40: 4.1 | G40: =IFERROR(__xludf.DUMMYFUNCTION("unique(filter(flatten(G98:G147,G154:G203,G210:G259,G266:G315,G322:G371,G378:G427,G434:G483),flatten(G98:G147,G154:G203,G210:G259,G266:G315,G322:G371,G378:G427,G434:G483)<>""""))"),"Hand") -> Hand | I40: =if(G40="","",vlookup(G40,Tools!$A$8:$E$177,5)) -> #REF! | J40: =IF(G40="","",(IF(COUNTIF(G$98:G$147,G40)>0,1,0)+IF(COUNTIF(G$154:G$203,G40)>0,1,0)+IF(COUNTIF(G$210:G$259,G40)>0,1,0)+IF(COUNTIF(G$266:G$315,G40)>0,1,0)+IF(COUNTIF(G$322:G$371,G40)>0,1,0)+IF(COUNTIF(G$378:G$427,G40)>0,1,0)+IF(COUNTIF(G$434:G$483,G40)>0,1,0))) -> 5 | K40: =IF(G40="","",(COUNTIF(G$98:G$147,G40)+COUNTIF(G$154:G$203,G40)+COUNTIF(G$210:G$259,G40)+COUNTIF(G$266:G$315,G40)+COUNTIF(G$322:G$371,G40)+COUNTIF(G$378:G$427,G40)+COUNTIF(G$434:G$483,G40))) -> 26 | L40: This list auto-populates based on tool entries in Disassembly + Reassembly Actions, below.
F41: 4.1 | G41: =IFERROR(__xludf.DUMMYFUNCTION("""COMPUTED_VALUE"""),"Screwdriver: Torx T5") -> Screwdriver: Torx T5 | I41: =if(G41="","",vlookup(G41,Tools!$A$8:$E$177,5)) -> #REF! | J41: =IF(G41="","",(IF(COUNTIF(G$98:G$147,G41)>0,1,0)+IF(COUNTIF(G$154:G$203,G41)>0,1,0)+IF(COUNTIF(G$210:G$259,G41)>0,1,0)+IF(COUNTIF(G$266:G$315,G41)>0,1,0)+IF(COUNTIF(G$322:G$371,G41)>0,1,0)+IF(COUNTIF(G$378:G$427,G41)>0,1,0)+IF(COUNTIF(G$434:G$483,G41)>0,1,0))) -> 5 | K41: =IF(G41="","",(COUNTIF(G$98:G$147,G41)+COUNTIF(G$154:G$203,G41)+COUNTIF(G$210:G$259,G41)+COUNTIF(G$266:G$315,G41)+COUNTIF(G$322:G$371,G41)+COUNTIF(G$378:G$427,G41)+COUNTIF(G$434:G$483,G41))) -> 5
F42: 4.1 | G42: =IFERROR(__xludf.DUMMYFUNCTION("""COMPUTED_VALUE"""),"Combo: Pick + Suction") -> Combo: Pick + Suction | I42: =if(G42="","",vlookup(G42,Tools!$A$8:$E$177,5)) -> #REF! | J42: =IF(G42="","",(IF(COUNTIF(G$98:G$147,G42)>0,1,0)+IF(COUNTIF(G$154:G$203,G42)>0,1,0)+IF(COUNTIF(G$210:G$259,G42)>0,1,0)+IF(COUNTIF(G$266:G$315,G42)>0,1,0)+IF(COUNTIF(G$322:G$371,G42)>0,1,0)+IF(COUNTIF(G$378:G$427,G42)>0,1,0)+IF(COUNTIF(G$434:G$483,G42)>0,1,0))) -> 4 | K42: =IF(G42="","",(COUNTIF(G$98:G$147,G42)+COUNTIF(G$154:G$203,G42)+COUNTIF(G$210:G$259,G42)+COUNTIF(G$266:G$315,G42)+COUNTIF(G$322:G$371,G42)+COUNTIF(G$378:G$427,G42)+COUNTIF(G$434:G$483,G42))) -> 4
F43: 4.1 | G43: =IFERROR(__xludf.DUMMYFUNCTION("""COMPUTED_VALUE"""),"Tweezers") -> Tweezers | I43: =if(G43="","",vlookup(G43,Tools!$A$8:$E$177,5)) -> #REF! | J43: =IF(G43="","",(IF(COUNTIF(G$98:G$147,G43)>0,1,0)+IF(COUNTIF(G$154:G$203,G43)>0,1,0)+IF(COUNTIF(G$210:G$259,G43)>0,1,0)+IF(COUNTIF(G$266:G$315,G43)>0,1,0)+IF(COUNTIF(G$322:G$371,G43)>0,1,0)+IF(COUNTIF(G$378:G$427,G43)>0,1,0)+IF(COUNTIF(G$434:G$483,G43)>0,1,0))) -> 5 | K43: =IF(G43="","",(COUNTIF(G$98:G$147,G43)+COUNTIF(G$154:G$203,G43)+COUNTIF(G$210:G$259,G43)+COUNTIF(G$266:G$315,G43)+COUNTIF(G$322:G$371,G43)+COUNTIF(G$378:G$427,G43)+COUNTIF(G$434:G$483,G43))) -> 28
...
